[2024-07-01 12:45:12,444: INFO: main: >>>>>> stage Data Ingestion stages started <<<<<<]
[2024-07-01 12:45:12,444: INFO: common: yaml file: config\config.yaml loaded successfully]
[2024-07-01 12:45:12,444: INFO: common: yaml file: params.yaml loaded successfully]
[2024-07-01 12:45:12,444: ERROR: main: Argument path_to_directories of type <class 'str'> to <function create_directories at 0x0000017AFFED5580> does not match annotation type <class 'list'>]
Traceback (most recent call last):
  File "C:\Users\Asus\OneDrive\Documents\Data Science\Coccidiosis_Chicken_Diseases_classification\main.py", line 9, in <module>
    obj.main()
  File "c:\users\asus\onedrive\documents\data science\coccidiosis_chicken_diseases_classification\src\cnnClassifier\pipeline\stage_01_data_ingestion.py", line 12, in main
    config = ConfigurationManager()
             ^^^^^^^^^^^^^^^^^^^^^^
  File "c:\users\asus\onedrive\documents\data science\coccidiosis_chicken_diseases_classification\src\cnnClassifier\config\configuration.py", line 14, in __init__
    create_directories(self.config.artifacts_root)
  File "C:\Python312\Lib\site-packages\ensure\main.py", line 803, in __call__
    raise EnsureError(msg.format(
ensure.main.EnsureError: Argument path_to_directories of type <class 'str'> to <function create_directories at 0x0000017AFFED5580> does not match annotation type <class 'list'>
[2024-07-01 12:50:59,055: INFO: main: >>>>>> stage Data Ingestion stages started <<<<<<]
[2024-07-01 12:50:59,055: INFO: common: yaml file: config\config.yaml loaded successfully]
[2024-07-01 12:50:59,071: INFO: common: yaml file: params.yaml loaded successfully]
[2024-07-01 12:50:59,071: ERROR: main: Argument path_to_directories of type <class 'str'> to <function create_directories at 0x0000020449D41580> does not match annotation type <class 'list'>]
Traceback (most recent call last):
  File "C:\Users\Asus\OneDrive\Documents\Data Science\Coccidiosis_Chicken_Diseases_classification\main.py", line 9, in <module>
    obj.main()
  File "c:\users\asus\onedrive\documents\data science\coccidiosis_chicken_diseases_classification\src\cnnClassifier\pipeline\stage_01_data_ingestion.py", line 12, in main
    config = ConfigurationManager()
             ^^^^^^^^^^^^^^^^^^^^^^
  File "c:\users\asus\onedrive\documents\data science\coccidiosis_chicken_diseases_classification\src\cnnClassifier\config\configuration.py", line 14, in __init__
    create_directories(self.config.artifacts_root)
  File "C:\Python312\Lib\site-packages\ensure\main.py", line 803, in __call__
    raise EnsureError(msg.format(
ensure.main.EnsureError: Argument path_to_directories of type <class 'str'> to <function create_directories at 0x0000020449D41580> does not match annotation type <class 'list'>
[2024-07-01 12:54:36,911: INFO: main: >>>>>> stage Data Ingestion stages started <<<<<<]
[2024-07-01 12:54:36,911: INFO: common: yaml file: config\config.yaml loaded successfully]
[2024-07-01 12:54:36,911: INFO: common: yaml file: params.yaml loaded successfully]
[2024-07-01 12:54:36,911: INFO: common: created directory at: artifacts]
[2024-07-01 12:54:36,911: ERROR: main: 'ConfigurationManager' object has no attribute 'congif']
Traceback (most recent call last):
  File "C:\Users\Asus\OneDrive\Documents\Data Science\Coccidiosis_Chicken_Diseases_classification\main.py", line 9, in <module>
    obj.main()
  File "c:\users\asus\onedrive\documents\data science\coccidiosis_chicken_diseases_classification\src\cnnClassifier\pipeline\stage_01_data_ingestion.py", line 13, in main
    data_ingestion_config = config.get_data_ingestion_config()
                            ^^^^^^^^^^^^^^^^^^^^^^^^^^^^^^^^^^
  File "c:\users\asus\onedrive\documents\data science\coccidiosis_chicken_diseases_classification\src\cnnClassifier\config\configuration.py", line 18, in get_data_ingestion_config
    config = self.congif.data_ingestion
             ^^^^^^^^^^^
AttributeError: 'ConfigurationManager' object has no attribute 'congif'. Did you mean: 'config'?
[2024-07-01 12:55:04,210: INFO: main: >>>>>> stage Data Ingestion stages started <<<<<<]
[2024-07-01 12:55:04,210: INFO: common: yaml file: config\config.yaml loaded successfully]
[2024-07-01 12:55:04,210: INFO: common: yaml file: params.yaml loaded successfully]
[2024-07-01 12:55:04,210: INFO: common: created directory at: artifacts]
[2024-07-01 12:55:04,217: INFO: common: created directory at: artifacts/data_ingestion]
[2024-07-01 12:55:04,226: ERROR: main: "'Box' object has no attribute 'source_url'"]
Traceback (most recent call last):
  File "C:\Python312\Lib\site-packages\box\box.py", line 503, in __getitem__
    return super().__getitem__(item)
           ^^^^^^^^^^^^^^^^^^^^^^^^^
KeyError: 'source_url'

The above exception was the direct cause of the following exception:

Traceback (most recent call last):
  File "C:\Python312\Lib\site-packages\box\box.py", line 536, in __getattr__
    value = self.__getitem__(item, _ignore_default=True)
            ^^^^^^^^^^^^^^^^^^^^^^^^^^^^^^^^^^^^^^^^^^^^
  File "C:\Python312\Lib\site-packages\box\box.py", line 524, in __getitem__
    raise BoxKeyError(str(err)) from _exception_cause(err)
box.exceptions.BoxKeyError: "'source_url'"

During handling of the above exception, another exception occurred:

Traceback (most recent call last):
  File "C:\Python312\Lib\site-packages\box\box.py", line 538, in __getattr__
    value = object.__getattribute__(self, item)
            ^^^^^^^^^^^^^^^^^^^^^^^^^^^^^^^^^^^
AttributeError: 'Box' object has no attribute 'source_url'. Did you mean: 'source_URL'?

The above exception was the direct cause of the following exception:

Traceback (most recent call last):
  File "C:\Users\Asus\OneDrive\Documents\Data Science\Coccidiosis_Chicken_Diseases_classification\main.py", line 9, in <module>
    obj.main()
  File "c:\users\asus\onedrive\documents\data science\coccidiosis_chicken_diseases_classification\src\cnnClassifier\pipeline\stage_01_data_ingestion.py", line 13, in main
    data_ingestion_config = config.get_data_ingestion_config()
                            ^^^^^^^^^^^^^^^^^^^^^^^^^^^^^^^^^^
  File "c:\users\asus\onedrive\documents\data science\coccidiosis_chicken_diseases_classification\src\cnnClassifier\config\configuration.py", line 24, in get_data_ingestion_config
    source_url=config.source_url,
               ^^^^^^^^^^^^^^^^^
  File "C:\Python312\Lib\site-packages\box\box.py", line 552, in __getattr__
    raise BoxKeyError(str(err)) from _exception_cause(err)
box.exceptions.BoxKeyError: "'Box' object has no attribute 'source_url'". Did you mean: 'source_URL'?
[2024-07-01 12:56:18,150: INFO: main: >>>>>> stage Data Ingestion stages started <<<<<<]
[2024-07-01 12:56:18,150: INFO: common: yaml file: config\config.yaml loaded successfully]
[2024-07-01 12:56:18,150: INFO: common: yaml file: params.yaml loaded successfully]
[2024-07-01 12:56:18,150: INFO: common: created directory at: artifacts]
[2024-07-01 12:56:18,150: INFO: common: created directory at: artifacts/data_ingestion]
[2024-07-01 12:56:18,150: ERROR: main: DataIngestionConfig.__init__() got an unexpected keyword argument 'roo0t_dir']
Traceback (most recent call last):
  File "C:\Users\Asus\OneDrive\Documents\Data Science\Coccidiosis_Chicken_Diseases_classification\main.py", line 9, in <module>
    obj.main()
  File "c:\users\asus\onedrive\documents\data science\coccidiosis_chicken_diseases_classification\src\cnnClassifier\pipeline\stage_01_data_ingestion.py", line 13, in main
    data_ingestion_config = config.get_data_ingestion_config()
                            ^^^^^^^^^^^^^^^^^^^^^^^^^^^^^^^^^^
  File "c:\users\asus\onedrive\documents\data science\coccidiosis_chicken_diseases_classification\src\cnnClassifier\config\configuration.py", line 22, in get_data_ingestion_config
    data_ingestion_config = DataIngestionConfig(
                            ^^^^^^^^^^^^^^^^^^^^
TypeError: DataIngestionConfig.__init__() got an unexpected keyword argument 'roo0t_dir'
[2024-07-01 12:56:49,891: INFO: main: >>>>>> stage Data Ingestion stages started <<<<<<]
[2024-07-01 12:56:49,891: INFO: common: yaml file: config\config.yaml loaded successfully]
[2024-07-01 12:56:49,901: INFO: common: yaml file: params.yaml loaded successfully]
[2024-07-01 12:56:49,901: INFO: common: created directory at: artifacts]
[2024-07-01 12:56:49,901: INFO: common: created directory at: artifacts/data_ingestion]
[2024-07-01 12:56:49,901: ERROR: main: DataIngestionConfig.__init__() got an unexpected keyword argument 'source_url']
Traceback (most recent call last):
  File "C:\Users\Asus\OneDrive\Documents\Data Science\Coccidiosis_Chicken_Diseases_classification\main.py", line 9, in <module>
    obj.main()
  File "c:\users\asus\onedrive\documents\data science\coccidiosis_chicken_diseases_classification\src\cnnClassifier\pipeline\stage_01_data_ingestion.py", line 13, in main
    data_ingestion_config = config.get_data_ingestion_config()
                            ^^^^^^^^^^^^^^^^^^^^^^^^^^^^^^^^^^
  File "c:\users\asus\onedrive\documents\data science\coccidiosis_chicken_diseases_classification\src\cnnClassifier\config\configuration.py", line 22, in get_data_ingestion_config
    data_ingestion_config = DataIngestionConfig(
                            ^^^^^^^^^^^^^^^^^^^^
TypeError: DataIngestionConfig.__init__() got an unexpected keyword argument 'source_url'
[2024-07-01 12:57:46,458: INFO: main: >>>>>> stage Data Ingestion stages started <<<<<<]
[2024-07-01 12:57:46,458: INFO: common: yaml file: config\config.yaml loaded successfully]
[2024-07-01 12:57:46,458: INFO: common: yaml file: params.yaml loaded successfully]
[2024-07-01 12:57:46,458: INFO: common: created directory at: artifacts]
[2024-07-01 12:57:46,458: INFO: common: created directory at: artifacts/data_ingestion]
[2024-07-01 12:57:55,235: INFO: data_ingestion: artifacts/data_ingestion/data.zip download! with following info: 
Connection: close
Content-Length: 11616915
Cache-Control: max-age=300
Content-Security-Policy: default-src 'none'; style-src 'unsafe-inline'; sandbox
Content-Type: application/zip
ETag: "adf745abc03891fe493c3be264ec012691fe3fa21d861f35a27edbe6d86a76b1"
Strict-Transport-Security: max-age=31536000
X-Content-Type-Options: nosniff
X-Frame-Options: deny
X-XSS-Protection: 1; mode=block
X-GitHub-Request-Id: 48B2:139ACD:64284F:77FDD8:66825A73
Accept-Ranges: bytes
Date: Mon, 01 Jul 2024 07:27:48 GMT
Via: 1.1 varnish
X-Served-By: cache-bom4726-BOM
X-Cache: MISS
X-Cache-Hits: 0
X-Timer: S1719818867.364171,VS0,VE927
Vary: Authorization,Accept-Encoding,Origin
Access-Control-Allow-Origin: *
Cross-Origin-Resource-Policy: cross-origin
X-Fastly-Request-ID: 8bf5447826ac55fb899423d257523b38209018ac
Expires: Mon, 01 Jul 2024 07:32:48 GMT
Source-Age: 0

]
[2024-07-01 12:57:55,520: INFO: data_ingestion: Zip file extracted to artifacts/data_ingestion]
[2024-07-01 12:57:55,520: INFO: main: >>>>>> stage Data Ingestion stages completed <<<<<<

x================x]
