[2024-07-01 12:45:12,444: INFO: main: >>>>>> stage Data Ingestion stages started <<<<<<]
[2024-07-01 12:45:12,444: INFO: common: yaml file: config\config.yaml loaded successfully]
[2024-07-01 12:45:12,444: INFO: common: yaml file: params.yaml loaded successfully]
[2024-07-01 12:45:12,444: ERROR: main: Argument path_to_directories of type <class 'str'> to <function create_directories at 0x0000017AFFED5580> does not match annotation type <class 'list'>]
Traceback (most recent call last):
  File "C:\Users\Asus\OneDrive\Documents\Data Science\Coccidiosis_Chicken_Diseases_classification\main.py", line 9, in <module>
    obj.main()
  File "c:\users\asus\onedrive\documents\data science\coccidiosis_chicken_diseases_classification\src\cnnClassifier\pipeline\stage_01_data_ingestion.py", line 12, in main
    config = ConfigurationManager()
             ^^^^^^^^^^^^^^^^^^^^^^
  File "c:\users\asus\onedrive\documents\data science\coccidiosis_chicken_diseases_classification\src\cnnClassifier\config\configuration.py", line 14, in __init__
    create_directories(self.config.artifacts_root)
  File "C:\Python312\Lib\site-packages\ensure\main.py", line 803, in __call__
    raise EnsureError(msg.format(
ensure.main.EnsureError: Argument path_to_directories of type <class 'str'> to <function create_directories at 0x0000017AFFED5580> does not match annotation type <class 'list'>
[2024-07-01 12:50:59,055: INFO: main: >>>>>> stage Data Ingestion stages started <<<<<<]
[2024-07-01 12:50:59,055: INFO: common: yaml file: config\config.yaml loaded successfully]
[2024-07-01 12:50:59,071: INFO: common: yaml file: params.yaml loaded successfully]
[2024-07-01 12:50:59,071: ERROR: main: Argument path_to_directories of type <class 'str'> to <function create_directories at 0x0000020449D41580> does not match annotation type <class 'list'>]
Traceback (most recent call last):
  File "C:\Users\Asus\OneDrive\Documents\Data Science\Coccidiosis_Chicken_Diseases_classification\main.py", line 9, in <module>
    obj.main()
  File "c:\users\asus\onedrive\documents\data science\coccidiosis_chicken_diseases_classification\src\cnnClassifier\pipeline\stage_01_data_ingestion.py", line 12, in main
    config = ConfigurationManager()
             ^^^^^^^^^^^^^^^^^^^^^^
  File "c:\users\asus\onedrive\documents\data science\coccidiosis_chicken_diseases_classification\src\cnnClassifier\config\configuration.py", line 14, in __init__
    create_directories(self.config.artifacts_root)
  File "C:\Python312\Lib\site-packages\ensure\main.py", line 803, in __call__
    raise EnsureError(msg.format(
ensure.main.EnsureError: Argument path_to_directories of type <class 'str'> to <function create_directories at 0x0000020449D41580> does not match annotation type <class 'list'>
[2024-07-01 12:54:36,911: INFO: main: >>>>>> stage Data Ingestion stages started <<<<<<]
[2024-07-01 12:54:36,911: INFO: common: yaml file: config\config.yaml loaded successfully]
[2024-07-01 12:54:36,911: INFO: common: yaml file: params.yaml loaded successfully]
[2024-07-01 12:54:36,911: INFO: common: created directory at: artifacts]
[2024-07-01 12:54:36,911: ERROR: main: 'ConfigurationManager' object has no attribute 'congif']
Traceback (most recent call last):
  File "C:\Users\Asus\OneDrive\Documents\Data Science\Coccidiosis_Chicken_Diseases_classification\main.py", line 9, in <module>
    obj.main()
  File "c:\users\asus\onedrive\documents\data science\coccidiosis_chicken_diseases_classification\src\cnnClassifier\pipeline\stage_01_data_ingestion.py", line 13, in main
    data_ingestion_config = config.get_data_ingestion_config()
                            ^^^^^^^^^^^^^^^^^^^^^^^^^^^^^^^^^^
  File "c:\users\asus\onedrive\documents\data science\coccidiosis_chicken_diseases_classification\src\cnnClassifier\config\configuration.py", line 18, in get_data_ingestion_config
    config = self.congif.data_ingestion
             ^^^^^^^^^^^
AttributeError: 'ConfigurationManager' object has no attribute 'congif'. Did you mean: 'config'?
[2024-07-01 12:55:04,210: INFO: main: >>>>>> stage Data Ingestion stages started <<<<<<]
[2024-07-01 12:55:04,210: INFO: common: yaml file: config\config.yaml loaded successfully]
[2024-07-01 12:55:04,210: INFO: common: yaml file: params.yaml loaded successfully]
[2024-07-01 12:55:04,210: INFO: common: created directory at: artifacts]
[2024-07-01 12:55:04,217: INFO: common: created directory at: artifacts/data_ingestion]
[2024-07-01 12:55:04,226: ERROR: main: "'Box' object has no attribute 'source_url'"]
Traceback (most recent call last):
  File "C:\Python312\Lib\site-packages\box\box.py", line 503, in __getitem__
    return super().__getitem__(item)
           ^^^^^^^^^^^^^^^^^^^^^^^^^
KeyError: 'source_url'

The above exception was the direct cause of the following exception:

Traceback (most recent call last):
  File "C:\Python312\Lib\site-packages\box\box.py", line 536, in __getattr__
    value = self.__getitem__(item, _ignore_default=True)
            ^^^^^^^^^^^^^^^^^^^^^^^^^^^^^^^^^^^^^^^^^^^^
  File "C:\Python312\Lib\site-packages\box\box.py", line 524, in __getitem__
    raise BoxKeyError(str(err)) from _exception_cause(err)
box.exceptions.BoxKeyError: "'source_url'"

During handling of the above exception, another exception occurred:

Traceback (most recent call last):
  File "C:\Python312\Lib\site-packages\box\box.py", line 538, in __getattr__
    value = object.__getattribute__(self, item)
            ^^^^^^^^^^^^^^^^^^^^^^^^^^^^^^^^^^^
AttributeError: 'Box' object has no attribute 'source_url'. Did you mean: 'source_URL'?

The above exception was the direct cause of the following exception:

Traceback (most recent call last):
  File "C:\Users\Asus\OneDrive\Documents\Data Science\Coccidiosis_Chicken_Diseases_classification\main.py", line 9, in <module>
    obj.main()
  File "c:\users\asus\onedrive\documents\data science\coccidiosis_chicken_diseases_classification\src\cnnClassifier\pipeline\stage_01_data_ingestion.py", line 13, in main
    data_ingestion_config = config.get_data_ingestion_config()
                            ^^^^^^^^^^^^^^^^^^^^^^^^^^^^^^^^^^
  File "c:\users\asus\onedrive\documents\data science\coccidiosis_chicken_diseases_classification\src\cnnClassifier\config\configuration.py", line 24, in get_data_ingestion_config
    source_url=config.source_url,
               ^^^^^^^^^^^^^^^^^
  File "C:\Python312\Lib\site-packages\box\box.py", line 552, in __getattr__
    raise BoxKeyError(str(err)) from _exception_cause(err)
box.exceptions.BoxKeyError: "'Box' object has no attribute 'source_url'". Did you mean: 'source_URL'?
[2024-07-01 12:56:18,150: INFO: main: >>>>>> stage Data Ingestion stages started <<<<<<]
[2024-07-01 12:56:18,150: INFO: common: yaml file: config\config.yaml loaded successfully]
[2024-07-01 12:56:18,150: INFO: common: yaml file: params.yaml loaded successfully]
[2024-07-01 12:56:18,150: INFO: common: created directory at: artifacts]
[2024-07-01 12:56:18,150: INFO: common: created directory at: artifacts/data_ingestion]
[2024-07-01 12:56:18,150: ERROR: main: DataIngestionConfig.__init__() got an unexpected keyword argument 'roo0t_dir']
Traceback (most recent call last):
  File "C:\Users\Asus\OneDrive\Documents\Data Science\Coccidiosis_Chicken_Diseases_classification\main.py", line 9, in <module>
    obj.main()
  File "c:\users\asus\onedrive\documents\data science\coccidiosis_chicken_diseases_classification\src\cnnClassifier\pipeline\stage_01_data_ingestion.py", line 13, in main
    data_ingestion_config = config.get_data_ingestion_config()
                            ^^^^^^^^^^^^^^^^^^^^^^^^^^^^^^^^^^
  File "c:\users\asus\onedrive\documents\data science\coccidiosis_chicken_diseases_classification\src\cnnClassifier\config\configuration.py", line 22, in get_data_ingestion_config
    data_ingestion_config = DataIngestionConfig(
                            ^^^^^^^^^^^^^^^^^^^^
TypeError: DataIngestionConfig.__init__() got an unexpected keyword argument 'roo0t_dir'
[2024-07-01 12:56:49,891: INFO: main: >>>>>> stage Data Ingestion stages started <<<<<<]
[2024-07-01 12:56:49,891: INFO: common: yaml file: config\config.yaml loaded successfully]
[2024-07-01 12:56:49,901: INFO: common: yaml file: params.yaml loaded successfully]
[2024-07-01 12:56:49,901: INFO: common: created directory at: artifacts]
[2024-07-01 12:56:49,901: INFO: common: created directory at: artifacts/data_ingestion]
[2024-07-01 12:56:49,901: ERROR: main: DataIngestionConfig.__init__() got an unexpected keyword argument 'source_url']
Traceback (most recent call last):
  File "C:\Users\Asus\OneDrive\Documents\Data Science\Coccidiosis_Chicken_Diseases_classification\main.py", line 9, in <module>
    obj.main()
  File "c:\users\asus\onedrive\documents\data science\coccidiosis_chicken_diseases_classification\src\cnnClassifier\pipeline\stage_01_data_ingestion.py", line 13, in main
    data_ingestion_config = config.get_data_ingestion_config()
                            ^^^^^^^^^^^^^^^^^^^^^^^^^^^^^^^^^^
  File "c:\users\asus\onedrive\documents\data science\coccidiosis_chicken_diseases_classification\src\cnnClassifier\config\configuration.py", line 22, in get_data_ingestion_config
    data_ingestion_config = DataIngestionConfig(
                            ^^^^^^^^^^^^^^^^^^^^
TypeError: DataIngestionConfig.__init__() got an unexpected keyword argument 'source_url'
[2024-07-01 12:57:46,458: INFO: main: >>>>>> stage Data Ingestion stages started <<<<<<]
[2024-07-01 12:57:46,458: INFO: common: yaml file: config\config.yaml loaded successfully]
[2024-07-01 12:57:46,458: INFO: common: yaml file: params.yaml loaded successfully]
[2024-07-01 12:57:46,458: INFO: common: created directory at: artifacts]
[2024-07-01 12:57:46,458: INFO: common: created directory at: artifacts/data_ingestion]
[2024-07-01 12:57:55,235: INFO: data_ingestion: artifacts/data_ingestion/data.zip download! with following info: 
Connection: close
Content-Length: 11616915
Cache-Control: max-age=300
Content-Security-Policy: default-src 'none'; style-src 'unsafe-inline'; sandbox
Content-Type: application/zip
ETag: "adf745abc03891fe493c3be264ec012691fe3fa21d861f35a27edbe6d86a76b1"
Strict-Transport-Security: max-age=31536000
X-Content-Type-Options: nosniff
X-Frame-Options: deny
X-XSS-Protection: 1; mode=block
X-GitHub-Request-Id: 48B2:139ACD:64284F:77FDD8:66825A73
Accept-Ranges: bytes
Date: Mon, 01 Jul 2024 07:27:48 GMT
Via: 1.1 varnish
X-Served-By: cache-bom4726-BOM
X-Cache: MISS
X-Cache-Hits: 0
X-Timer: S1719818867.364171,VS0,VE927
Vary: Authorization,Accept-Encoding,Origin
Access-Control-Allow-Origin: *
Cross-Origin-Resource-Policy: cross-origin
X-Fastly-Request-ID: 8bf5447826ac55fb899423d257523b38209018ac
Expires: Mon, 01 Jul 2024 07:32:48 GMT
Source-Age: 0

]
[2024-07-01 12:57:55,520: INFO: data_ingestion: Zip file extracted to artifacts/data_ingestion]
[2024-07-01 12:57:55,520: INFO: main: >>>>>> stage Data Ingestion stages completed <<<<<<

x================x]
[2024-07-01 17:00:58,767: INFO: main: >>>>>> stage Data Ingestion stages started <<<<<<]
[2024-07-01 17:00:58,767: INFO: common: yaml file: config\config.yaml loaded successfully]
[2024-07-01 17:00:58,767: INFO: common: yaml file: params.yaml loaded successfully]
[2024-07-01 17:00:58,767: INFO: common: created directory at: artifacts]
[2024-07-01 17:00:58,767: INFO: common: created directory at: artifacts/data_ingestion]
[2024-07-01 17:01:10,750: INFO: data_ingestion: artifacts/data_ingestion/data.zip download! with following info: 
Connection: close
Content-Length: 11616915
Cache-Control: max-age=300
Content-Security-Policy: default-src 'none'; style-src 'unsafe-inline'; sandbox
Content-Type: application/zip
ETag: "adf745abc03891fe493c3be264ec012691fe3fa21d861f35a27edbe6d86a76b1"
Strict-Transport-Security: max-age=31536000
X-Content-Type-Options: nosniff
X-Frame-Options: deny
X-XSS-Protection: 1; mode=block
X-GitHub-Request-Id: 4DC1:2127A0:1ECE49:24698D:66829372
Accept-Ranges: bytes
Date: Mon, 01 Jul 2024 11:31:00 GMT
Via: 1.1 varnish
X-Served-By: cache-bom4730-BOM
X-Cache: MISS
X-Cache-Hits: 0
X-Timer: S1719833460.532904,VS0,VE1030
Vary: Authorization,Accept-Encoding,Origin
Access-Control-Allow-Origin: *
Cross-Origin-Resource-Policy: cross-origin
X-Fastly-Request-ID: 7158a35b53be59585f6ac6cb55cc9a20495cbe8f
Expires: Mon, 01 Jul 2024 11:36:00 GMT
Source-Age: 1

]
[2024-07-01 17:01:11,079: INFO: data_ingestion: Zip file extracted to artifacts/data_ingestion]
[2024-07-01 17:01:11,081: INFO: main: >>>>>> stage Data Ingestion stages completed <<<<<<

x================x]
[2024-07-01 17:01:11,081: INFO: main: >>>>>> stage Prepare Base Model stage started <<<<<<]
[2024-07-01 17:01:11,081: INFO: common: yaml file: config\config.yaml loaded successfully]
[2024-07-01 17:01:11,081: INFO: common: yaml file: params.yaml loaded successfully]
[2024-07-01 17:01:11,081: INFO: common: created directory at: artifacts]
[2024-07-01 17:01:11,081: INFO: common: created directory at: artifacts/prepare_base_model]
[2024-07-01 17:01:11,081: ERROR: main: "'Box' object has no attribute 'based_model_path'"]
Traceback (most recent call last):
  File "C:\Python312\Lib\site-packages\box\box.py", line 503, in __getitem__
    return super().__getitem__(item)
           ^^^^^^^^^^^^^^^^^^^^^^^^^
KeyError: 'based_model_path'

The above exception was the direct cause of the following exception:

Traceback (most recent call last):
  File "C:\Python312\Lib\site-packages\box\box.py", line 536, in __getattr__
    value = self.__getitem__(item, _ignore_default=True)
            ^^^^^^^^^^^^^^^^^^^^^^^^^^^^^^^^^^^^^^^^^^^^
  File "C:\Python312\Lib\site-packages\box\box.py", line 524, in __getitem__
    raise BoxKeyError(str(err)) from _exception_cause(err)
box.exceptions.BoxKeyError: "'based_model_path'"

During handling of the above exception, another exception occurred:

Traceback (most recent call last):
  File "C:\Python312\Lib\site-packages\box\box.py", line 538, in __getattr__
    value = object.__getattribute__(self, item)
            ^^^^^^^^^^^^^^^^^^^^^^^^^^^^^^^^^^^
AttributeError: 'Box' object has no attribute 'based_model_path'. Did you mean: 'base_model_path'?

The above exception was the direct cause of the following exception:

Traceback (most recent call last):
  File "C:\Users\Asus\OneDrive\Documents\Data Science\Coccidiosis_Chicken_Diseases_classification\main.py", line 21, in <module>
    obj.main()
  File "c:\users\asus\onedrive\documents\data science\coccidiosis_chicken_diseases_classification\src\cnnClassifier\pipeline\stage_02_prepare_base_model.py", line 13, in main
    prepare_base_model_config = config.get_prepare_base_model_config()
                                ^^^^^^^^^^^^^^^^^^^^^^^^^^^^^^^^^^^^^^
  File "c:\users\asus\onedrive\documents\data science\coccidiosis_chicken_diseases_classification\src\cnnClassifier\config\configuration.py", line 40, in get_prepare_base_model_config
    based_model_path=Path(config.based_model_path),
                          ^^^^^^^^^^^^^^^^^^^^^^^
  File "C:\Python312\Lib\site-packages\box\box.py", line 552, in __getattr__
    raise BoxKeyError(str(err)) from _exception_cause(err)
box.exceptions.BoxKeyError: "'Box' object has no attribute 'based_model_path'". Did you mean: 'base_model_path'?
[2024-07-01 17:05:08,369: INFO: main: >>>>>> stage Data Ingestion stages started <<<<<<]
[2024-07-01 17:05:08,369: INFO: common: yaml file: config\config.yaml loaded successfully]
[2024-07-01 17:05:08,369: INFO: common: yaml file: params.yaml loaded successfully]
[2024-07-01 17:05:08,369: INFO: common: created directory at: artifacts]
[2024-07-01 17:05:08,369: INFO: common: created directory at: artifacts/data_ingestion]
[2024-07-01 17:05:08,369: INFO: data_ingestion: File already exists of size: 11345 KB]
[2024-07-01 17:05:08,542: INFO: data_ingestion: Zip file extracted to artifacts/data_ingestion]
[2024-07-01 17:05:08,542: INFO: main: >>>>>> stage Data Ingestion stages completed <<<<<<

x================x]
[2024-07-01 17:05:08,542: INFO: main: >>>>>> stage Prepare Base Model stage started <<<<<<]
[2024-07-01 17:05:08,542: INFO: common: yaml file: config\config.yaml loaded successfully]
[2024-07-01 17:05:08,542: INFO: common: yaml file: params.yaml loaded successfully]
[2024-07-01 17:05:08,542: INFO: common: created directory at: artifacts]
[2024-07-01 17:05:08,542: INFO: common: created directory at: artifacts/prepare_base_model]
[2024-07-01 17:05:09,019: ERROR: main: PrepareBaseModel.save_model() got multiple values for argument 'path']
Traceback (most recent call last):
  File "C:\Users\Asus\OneDrive\Documents\Data Science\Coccidiosis_Chicken_Diseases_classification\main.py", line 21, in <module>
    obj.main()
  File "c:\users\asus\onedrive\documents\data science\coccidiosis_chicken_diseases_classification\src\cnnClassifier\pipeline\stage_02_prepare_base_model.py", line 15, in main
    prepare_base_model.get_base_model()
  File "c:\users\asus\onedrive\documents\data science\coccidiosis_chicken_diseases_classification\src\cnnClassifier\components\prepare_base_model.py", line 17, in get_base_model
    self.save_model(path=self.config.base_model_path, model=self.model)
TypeError: PrepareBaseModel.save_model() got multiple values for argument 'path'
[2024-07-01 17:15:51,516: INFO: main: >>>>>> stage Data Ingestion stages started <<<<<<]
[2024-07-01 17:15:51,516: INFO: common: yaml file: config\config.yaml loaded successfully]
[2024-07-01 17:15:51,516: INFO: common: yaml file: params.yaml loaded successfully]
[2024-07-01 17:15:51,516: INFO: common: created directory at: artifacts]
[2024-07-01 17:15:51,516: INFO: common: created directory at: artifacts/data_ingestion]
[2024-07-01 17:15:57,808: INFO: data_ingestion: artifacts/data_ingestion/data.zip download! with following info: 
Connection: close
Content-Length: 11616915
Cache-Control: max-age=300
Content-Security-Policy: default-src 'none'; style-src 'unsafe-inline'; sandbox
Content-Type: application/zip
ETag: "adf745abc03891fe493c3be264ec012691fe3fa21d861f35a27edbe6d86a76b1"
Strict-Transport-Security: max-age=31536000
X-Content-Type-Options: nosniff
X-Frame-Options: deny
X-XSS-Protection: 1; mode=block
X-GitHub-Request-Id: 4DC1:2127A0:1ECE49:24698D:66829372
Accept-Ranges: bytes
Date: Mon, 01 Jul 2024 11:45:52 GMT
Via: 1.1 varnish
X-Served-By: cache-bom4725-BOM
X-Cache: HIT
X-Cache-Hits: 0
X-Timer: S1719834352.098343,VS0,VE341
Vary: Authorization,Accept-Encoding,Origin
Access-Control-Allow-Origin: *
Cross-Origin-Resource-Policy: cross-origin
X-Fastly-Request-ID: 292d9c2f57de265c88760cfaf54542d887ad02f4
Expires: Mon, 01 Jul 2024 11:50:52 GMT
Source-Age: 0

]
[2024-07-01 17:15:58,078: INFO: data_ingestion: Zip file extracted to artifacts/data_ingestion]
[2024-07-01 17:15:58,078: INFO: main: >>>>>> stage Data Ingestion stages completed <<<<<<

x================x]
[2024-07-01 17:15:58,078: INFO: main: >>>>>> stage Prepare Base Model stage started <<<<<<]
[2024-07-01 17:15:58,078: INFO: common: yaml file: config\config.yaml loaded successfully]
[2024-07-01 17:15:58,078: INFO: common: yaml file: params.yaml loaded successfully]
[2024-07-01 17:15:58,078: INFO: common: created directory at: artifacts]
[2024-07-01 17:15:58,078: INFO: common: created directory at: artifacts/prepare_base_model]
[2024-07-01 17:15:58,568: WARNING: saving_api: You are saving your model as an HDF5 file via `model.save()` or `keras.saving.save_model(model)`. This file format is considered legacy. We recommend using instead the native Keras format, e.g. `model.save('my_model.keras')` or `keras.saving.save_model(model, 'my_model.keras')`. ]
[2024-07-01 17:15:58,726: ERROR: main: Argument(s) not recognized: {'Learning_rate': 0.01}]
Traceback (most recent call last):
  File "C:\Users\Asus\OneDrive\Documents\Data Science\Coccidiosis_Chicken_Diseases_classification\main.py", line 21, in <module>
    obj.main()
  File "c:\users\asus\onedrive\documents\data science\coccidiosis_chicken_diseases_classification\src\cnnClassifier\pipeline\stage_02_prepare_base_model.py", line 16, in main
    prepare_base_model.update_base_model()
  File "c:\users\asus\onedrive\documents\data science\coccidiosis_chicken_diseases_classification\src\cnnClassifier\components\prepare_base_model.py", line 49, in update_base_model
    self.full_model = self._prepare_full_model(
                      ^^^^^^^^^^^^^^^^^^^^^^^^^
  File "c:\users\asus\onedrive\documents\data science\coccidiosis_chicken_diseases_classification\src\cnnClassifier\components\prepare_base_model.py", line 40, in _prepare_full_model
    optimizer=tf.keras.optimizers.SGD(Learning_rate=Learning_rate),
              ^^^^^^^^^^^^^^^^^^^^^^^^^^^^^^^^^^^^^^^^^^^^^^^^^^^^
  File "C:\Python312\Lib\site-packages\keras\src\optimizers\sgd.py", line 60, in __init__
    super().__init__(
  File "C:\Python312\Lib\site-packages\keras\src\backend\tensorflow\optimizer.py", line 22, in __init__
    super().__init__(*args, **kwargs)
  File "C:\Python312\Lib\site-packages\keras\src\optimizers\base_optimizer.py", line 37, in __init__
    raise ValueError(f"Argument(s) not recognized: {kwargs}")
ValueError: Argument(s) not recognized: {'Learning_rate': 0.01}
[2024-07-01 17:17:58,214: INFO: main: >>>>>> stage Data Ingestion stages started <<<<<<]
[2024-07-01 17:17:58,216: INFO: common: yaml file: config\config.yaml loaded successfully]
[2024-07-01 17:17:58,217: INFO: common: yaml file: params.yaml loaded successfully]
[2024-07-01 17:17:58,217: INFO: common: created directory at: artifacts]
[2024-07-01 17:17:58,217: INFO: common: created directory at: artifacts/data_ingestion]
[2024-07-01 17:18:08,376: INFO: data_ingestion: artifacts/data_ingestion/data.zip download! with following info: 
Connection: close
Content-Length: 11616915
Cache-Control: max-age=300
Content-Security-Policy: default-src 'none'; style-src 'unsafe-inline'; sandbox
Content-Type: application/zip
ETag: "adf745abc03891fe493c3be264ec012691fe3fa21d861f35a27edbe6d86a76b1"
Strict-Transport-Security: max-age=31536000
X-Content-Type-Options: nosniff
X-Frame-Options: deny
X-XSS-Protection: 1; mode=block
X-GitHub-Request-Id: 4DC1:2127A0:1ECE49:24698D:66829372
Accept-Ranges: bytes
Date: Mon, 01 Jul 2024 11:47:58 GMT
Via: 1.1 varnish
X-Served-By: cache-bom4722-BOM
X-Cache: HIT
X-Cache-Hits: 0
X-Timer: S1719834478.440012,VS0,VE1
Vary: Authorization,Accept-Encoding,Origin
Access-Control-Allow-Origin: *
Cross-Origin-Resource-Policy: cross-origin
X-Fastly-Request-ID: 1e98591f7ede8d1f1b7ae5386e79a2e72266b241
Expires: Mon, 01 Jul 2024 11:52:58 GMT
Source-Age: 126

]
[2024-07-01 17:18:08,607: INFO: data_ingestion: Zip file extracted to artifacts/data_ingestion]
[2024-07-01 17:18:08,607: INFO: main: >>>>>> stage Data Ingestion stages completed <<<<<<

x================x]
[2024-07-01 17:18:08,607: INFO: main: >>>>>> stage Prepare Base Model stage started <<<<<<]
[2024-07-01 17:18:08,607: INFO: common: yaml file: config\config.yaml loaded successfully]
[2024-07-01 17:18:08,607: INFO: common: yaml file: params.yaml loaded successfully]
[2024-07-01 17:18:08,623: INFO: common: created directory at: artifacts]
[2024-07-01 17:18:08,623: INFO: common: created directory at: artifacts/prepare_base_model]
[2024-07-01 17:18:09,098: WARNING: saving_api: You are saving your model as an HDF5 file via `model.save()` or `keras.saving.save_model(model)`. This file format is considered legacy. We recommend using instead the native Keras format, e.g. `model.save('my_model.keras')` or `keras.saving.save_model(model, 'my_model.keras')`. ]
[2024-07-01 17:18:09,429: ERROR: main: Trainer.compile() got an unexpected keyword argument 'Loss']
Traceback (most recent call last):
  File "C:\Users\Asus\OneDrive\Documents\Data Science\Coccidiosis_Chicken_Diseases_classification\main.py", line 21, in <module>
    obj.main()
  File "c:\users\asus\onedrive\documents\data science\coccidiosis_chicken_diseases_classification\src\cnnClassifier\pipeline\stage_02_prepare_base_model.py", line 16, in main
    prepare_base_model.update_base_model()
  File "c:\users\asus\onedrive\documents\data science\coccidiosis_chicken_diseases_classification\src\cnnClassifier\components\prepare_base_model.py", line 49, in update_base_model
    self.full_model = self._prepare_full_model(
                      ^^^^^^^^^^^^^^^^^^^^^^^^^
  File "c:\users\asus\onedrive\documents\data science\coccidiosis_chicken_diseases_classification\src\cnnClassifier\components\prepare_base_model.py", line 39, in _prepare_full_model
    full_model.compile(
  File "C:\Python312\Lib\site-packages\keras\src\utils\traceback_utils.py", line 122, in error_handler
    raise e.with_traceback(filtered_tb) from None
  File "C:\Python312\Lib\site-packages\keras\src\utils\tracking.py", line 26, in wrapper
    return fn(*args, **kwargs)
           ^^^^^^^^^^^^^^^^^^^
TypeError: Trainer.compile() got an unexpected keyword argument 'Loss'
[2024-07-01 17:18:52,905: INFO: main: >>>>>> stage Data Ingestion stages started <<<<<<]
[2024-07-01 17:18:52,905: INFO: common: yaml file: config\config.yaml loaded successfully]
[2024-07-01 17:18:52,905: INFO: common: yaml file: params.yaml loaded successfully]
[2024-07-01 17:18:52,921: INFO: common: created directory at: artifacts]
[2024-07-01 17:18:52,921: INFO: common: created directory at: artifacts/data_ingestion]
[2024-07-01 17:18:59,140: INFO: data_ingestion: artifacts/data_ingestion/data.zip download! with following info: 
Connection: close
Content-Length: 11616915
Cache-Control: max-age=300
Content-Security-Policy: default-src 'none'; style-src 'unsafe-inline'; sandbox
Content-Type: application/zip
ETag: "adf745abc03891fe493c3be264ec012691fe3fa21d861f35a27edbe6d86a76b1"
Strict-Transport-Security: max-age=31536000
X-Content-Type-Options: nosniff
X-Frame-Options: deny
X-XSS-Protection: 1; mode=block
X-GitHub-Request-Id: 4DC1:2127A0:1ECE49:24698D:66829372
Accept-Ranges: bytes
Date: Mon, 01 Jul 2024 11:48:53 GMT
Via: 1.1 varnish
X-Served-By: cache-bom4721-BOM
X-Cache: HIT
X-Cache-Hits: 0
X-Timer: S1719834533.213011,VS0,VE1
Vary: Authorization,Accept-Encoding,Origin
Access-Control-Allow-Origin: *
Cross-Origin-Resource-Policy: cross-origin
X-Fastly-Request-ID: 60d7c3358a1d993158f23141c1fcb83a0035ebd1
Expires: Mon, 01 Jul 2024 11:53:53 GMT
Source-Age: 181

]
[2024-07-01 17:18:59,377: INFO: data_ingestion: Zip file extracted to artifacts/data_ingestion]
[2024-07-01 17:18:59,377: INFO: main: >>>>>> stage Data Ingestion stages completed <<<<<<

x================x]
[2024-07-01 17:18:59,377: INFO: main: >>>>>> stage Prepare Base Model stage started <<<<<<]
[2024-07-01 17:18:59,377: INFO: common: yaml file: config\config.yaml loaded successfully]
[2024-07-01 17:18:59,377: INFO: common: yaml file: params.yaml loaded successfully]
[2024-07-01 17:18:59,377: INFO: common: created directory at: artifacts]
[2024-07-01 17:18:59,377: INFO: common: created directory at: artifacts/prepare_base_model]
[2024-07-01 17:18:59,804: WARNING: saving_api: You are saving your model as an HDF5 file via `model.save()` or `keras.saving.save_model(model)`. This file format is considered legacy. We recommend using instead the native Keras format, e.g. `model.save('my_model.keras')` or `keras.saving.save_model(model, 'my_model.keras')`. ]
[2024-07-01 17:18:59,931: WARNING: saving_api: You are saving your model as an HDF5 file via `model.save()` or `keras.saving.save_model(model)`. This file format is considered legacy. We recommend using instead the native Keras format, e.g. `model.save('my_model.keras')` or `keras.saving.save_model(model, 'my_model.keras')`. ]
[2024-07-01 17:19:00,041: INFO: main: >>>>>> stage Prepare Base Model stage completed <<<<<<

x================x]
